2024-08-24 12:55:34,830 - WARNING - PyNaCl is not installed, voice will NOT be supported
2024-08-24 12:55:34,832 - INFO - 設定ファイルが再読み込みされました。
2024-08-24 12:55:34,837 - INFO - logging in using static token
2024-08-24 12:55:36,013 - INFO - Shard ID None has connected to Gateway (Session ID: 5072c6e87873bc0bc56c57b87a40d0e2).
2024-08-24 12:55:38,039 - INFO - ログインしました: レシピリサーチャーBot (814286584509104178)
2024-08-24 13:51:51,799 - WARNING - PyNaCl is not installed, voice will NOT be supported
2024-08-24 13:51:51,801 - INFO - 設定ファイルが再読み込みされました。
2024-08-24 13:51:51,804 - INFO - logging in using static token
2024-08-24 13:51:53,070 - INFO - Shard ID None has connected to Gateway (Session ID: b7431370f17158a902ad2f508b0a0b97).
2024-08-24 13:51:55,093 - INFO - ログインしました: レシピリサーチャーBot (814286584509104178)
2024-08-24 18:48:36,356 - WARNING - PyNaCl is not installed, voice will NOT be supported
2024-08-24 18:48:36,362 - INFO - 設定ファイルが再読み込みされました。
2024-08-24 18:48:36,365 - INFO - logging in using static token
2024-08-24 18:48:37,500 - INFO - Shard ID None has connected to Gateway (Session ID: 4a8f1d8bd9ed5e6d3fff247ef6b62ee2).
2024-08-24 18:48:39,510 - INFO - ログインしました: レシピリサーチャーBot (814286584509104178)
2024-08-24 18:54:23,392 - WARNING - PyNaCl is not installed, voice will NOT be supported
2024-08-24 18:54:23,394 - INFO - 設定ファイルが再読み込みされました。
2024-08-24 18:54:23,397 - INFO - logging in using static token
2024-08-24 18:54:24,539 - INFO - Shard ID None has connected to Gateway (Session ID: eac4ca407ba36477f10bdf8f5f95b81f).
2024-08-24 18:54:26,556 - INFO - ログインしました: レシピリサーチャーBot (814286584509104178)
2024-08-24 18:56:29,761 - WARNING - PyNaCl is not installed, voice will NOT be supported
2024-08-24 18:56:29,763 - INFO - 設定ファイルが再読み込みされました。
2024-08-24 18:56:29,766 - INFO - logging in using static token
2024-08-24 18:56:30,927 - INFO - Shard ID None has connected to Gateway (Session ID: b547eb395e15d82f11813f64d3ba89aa).
2024-08-24 18:56:32,965 - INFO - ログインしました: レシピリサーチャーBot (814286584509104178)
2024-08-24 18:58:14,066 - WARNING - PyNaCl is not installed, voice will NOT be supported
2024-08-24 18:58:14,068 - INFO - 設定ファイルが再読み込みされました。
2024-08-24 18:58:14,071 - INFO - logging in using static token
2024-08-24 18:58:15,133 - INFO - Shard ID None has connected to Gateway (Session ID: 544e8547453946fb363c2cf599d818f1).
2024-08-24 18:58:17,138 - INFO - ログインしました: レシピリサーチャーBot (814286584509104178)
2024-08-24 19:00:04,051 - WARNING - PyNaCl is not installed, voice will NOT be supported
2024-08-24 19:00:04,053 - INFO - 設定ファイルが再読み込みされました。
2024-08-24 19:00:04,057 - INFO - logging in using static token
2024-08-24 19:00:05,384 - INFO - Shard ID None has connected to Gateway (Session ID: 559ba00dda25f91633f8897232ef5aef).
2024-08-24 19:00:07,395 - INFO - ログインしました: レシピリサーチャーBot (814286584509104178)
2024-08-24 20:13:17,244 - WARNING - PyNaCl is not installed, voice will NOT be supported
2024-08-24 20:13:17,246 - INFO - 設定ファイルが再読み込みされました。
2024-08-24 20:13:17,249 - INFO - logging in using static token
2024-08-24 20:13:18,316 - INFO - Shard ID None has connected to Gateway (Session ID: c0e0b7a5440a1be53d4173f6f0ad91b9).
2024-08-24 20:13:20,345 - INFO - ログインしました: レシピリサーチャーBot (814286584509104178)
2024-08-24 20:14:52,471 - WARNING - PyNaCl is not installed, voice will NOT be supported
2024-08-24 20:14:52,474 - INFO - 設定ファイルが再読み込みされました。
2024-08-24 20:14:57,479 - INFO - logging in using static token
2024-08-24 20:14:58,661 - INFO - Shard ID None has connected to Gateway (Session ID: 4c4278368d2e179bc1324d6795802700).
2024-08-24 20:15:00,711 - INFO - ログインしました: レシピリサーチャーBot (814286584509104178)
2024-08-24 20:15:15,109 - WARNING - PyNaCl is not installed, voice will NOT be supported
2024-08-24 20:15:15,110 - INFO - 設定ファイルが再読み込みされました。
2024-08-24 20:15:15,112 - INFO - logging in using static token
2024-08-24 20:15:16,199 - INFO - Shard ID None has connected to Gateway (Session ID: 78e7a1e469239d9b05794b8ada76ef2a).
2024-08-24 20:15:18,236 - INFO - ログインしました: レシピリサーチャーBot (814286584509104178)
2024-08-24 20:15:37,408 - WARNING - PyNaCl is not installed, voice will NOT be supported
2024-08-24 20:15:37,410 - INFO - 設定ファイルが再読み込みされました。
2024-08-24 20:15:37,412 - INFO - logging in using static token
2024-08-24 20:15:38,511 - INFO - Shard ID None has connected to Gateway (Session ID: 4a7f9f558b85486a4864cb5b6e0fff2a).
2024-08-24 20:15:40,523 - INFO - ログインしました: レシピリサーチャーBot (814286584509104178)
2024-08-24 20:16:36,180 - WARNING - PyNaCl is not installed, voice will NOT be supported
2024-08-24 20:16:36,185 - INFO - 設定ファイルが再読み込みされました。
2024-08-24 20:16:36,208 - INFO - logging in using static token
2024-08-24 20:16:37,286 - INFO - Shard ID None has connected to Gateway (Session ID: ae25ce84b64ab35d59ca8f346dce54ff).
2024-08-24 20:16:39,296 - INFO - ログインしました: レシピリサーチャーBot (814286584509104178)
2024-08-24 20:20:11,318 - WARNING - PyNaCl is not installed, voice will NOT be supported
2024-08-24 20:20:11,320 - INFO - 設定ファイルが再読み込みされました。
2024-08-24 20:20:11,324 - INFO - logging in using static token
2024-08-24 20:20:12,513 - INFO - Shard ID None has connected to Gateway (Session ID: f00729e8767f97b0b23d89eaf169b216).
2024-08-24 20:20:14,541 - INFO - ログインしました: レシピリサーチャーBot (814286584509104178)
2024-08-24 20:20:26,246 - ERROR - 材料コマンドの形式エラー: not enough values to unpack (expected 2, got 1)
2024-08-24 20:20:32,916 - ERROR - 材料コマンドの形式エラー: not enough values to unpack (expected 2, got 1)
2024-08-24 20:22:26,418 - WARNING - PyNaCl is not installed, voice will NOT be supported
2024-08-24 20:22:26,420 - INFO - 設定ファイルが再読み込みされました。
2024-08-24 20:22:26,423 - INFO - logging in using static token
2024-08-24 20:22:27,520 - INFO - Shard ID None has connected to Gateway (Session ID: 45485c1561a17968892308920c80b1c4).
2024-08-24 20:22:29,589 - INFO - ログインしました: レシピリサーチャーBot (814286584509104178)
2024-08-24 20:26:19,014 - ERROR - 材料コマンドの形式エラー: not enough values to unpack (expected 2, got 1)
2024-08-24 20:26:25,511 - ERROR - 材料コマンドの形式エラー: invalid literal for int() with base 10: ''
2024-08-24 20:38:27,516 - WARNING - PyNaCl is not installed, voice will NOT be supported
2024-08-24 20:38:27,518 - INFO - 設定ファイルが再読み込みされました。
2024-08-24 20:38:27,521 - INFO - logging in using static token
2024-08-24 20:38:28,573 - INFO - Shard ID None has connected to Gateway (Session ID: 63473e0f8f8f5e2fb5657324134de962).
2024-08-24 20:38:30,609 - INFO - ログインしました: レシピリサーチャーBot (814286584509104178)
2024-08-24 20:39:26,104 - ERROR - Ignoring exception in command 'materials'
Traceback (most recent call last):
  File "C:\Users\matum\AppData\Local\Packages\PythonSoftwareFoundation.Python.3.11_qbz5n2kfra8p0\LocalCache\local-packages\Python311\site-packages\discord\app_commands\commands.py", line 858, in _do_call
    return await self._callback(interaction, **params)  # type: ignore
           ^^^^^^^^^^^^^^^^^^^^^^^^^^^^^^^^^^^^^^^^^^^
  File "E:\Prg\Python\RecipeResearcher\RecipeResearcherBot_default_quantity.py", line 162, in materials
    key, value = line.strip().split(':')
    ^^^^^^^^^^
ValueError: not enough values to unpack (expected 2, got 1)

The above exception was the direct cause of the following exception:

Traceback (most recent call last):
  File "C:\Users\matum\AppData\Local\Packages\PythonSoftwareFoundation.Python.3.11_qbz5n2kfra8p0\LocalCache\local-packages\Python311\site-packages\discord\app_commands\tree.py", line 1310, in _call
    await command._invoke_with_namespace(interaction, namespace)
  File "C:\Users\matum\AppData\Local\Packages\PythonSoftwareFoundation.Python.3.11_qbz5n2kfra8p0\LocalCache\local-packages\Python311\site-packages\discord\app_commands\commands.py", line 883, in _invoke_with_namespace
    return await self._do_call(interaction, transformed_values)
           ^^^^^^^^^^^^^^^^^^^^^^^^^^^^^^^^^^^^^^^^^^^^^^^^^^^^
  File "C:\Users\matum\AppData\Local\Packages\PythonSoftwareFoundation.Python.3.11_qbz5n2kfra8p0\LocalCache\local-packages\Python311\site-packages\discord\app_commands\commands.py", line 876, in _do_call
    raise CommandInvokeError(self, e) from e
discord.app_commands.errors.CommandInvokeError: Command 'materials' raised an exception: ValueError: not enough values to unpack (expected 2, got 1)
2024-08-24 20:40:50,951 - WARNING - PyNaCl is not installed, voice will NOT be supported
2024-08-24 20:40:50,953 - INFO - 設定ファイルが再読み込みされました。
2024-08-24 20:40:50,956 - INFO - logging in using static token
2024-08-24 20:40:52,145 - INFO - Shard ID None has connected to Gateway (Session ID: fba593358bc3637898ca842eda9e3050).
2024-08-24 20:40:54,165 - INFO - ログインしました: レシピリサーチャーBot (814286584509104178)
2024-08-24 20:40:55,644 - ERROR - Ignoring exception in command 'materials'
Traceback (most recent call last):
  File "C:\Users\matum\AppData\Local\Packages\PythonSoftwareFoundation.Python.3.11_qbz5n2kfra8p0\LocalCache\local-packages\Python311\site-packages\discord\app_commands\commands.py", line 858, in _do_call
    return await self._callback(interaction, **params)  # type: ignore
           ^^^^^^^^^^^^^^^^^^^^^^^^^^^^^^^^^^^^^^^^^^^
  File "E:\Prg\Python\RecipeResearcher\RecipeResearcherBot_default_quantity.py", line 163, in materials
    key, value = line.strip().split(':')
    ^^^^^^^^^^
ValueError: not enough values to unpack (expected 2, got 1)

The above exception was the direct cause of the following exception:

Traceback (most recent call last):
  File "C:\Users\matum\AppData\Local\Packages\PythonSoftwareFoundation.Python.3.11_qbz5n2kfra8p0\LocalCache\local-packages\Python311\site-packages\discord\app_commands\tree.py", line 1310, in _call
    await command._invoke_with_namespace(interaction, namespace)
  File "C:\Users\matum\AppData\Local\Packages\PythonSoftwareFoundation.Python.3.11_qbz5n2kfra8p0\LocalCache\local-packages\Python311\site-packages\discord\app_commands\commands.py", line 883, in _invoke_with_namespace
    return await self._do_call(interaction, transformed_values)
           ^^^^^^^^^^^^^^^^^^^^^^^^^^^^^^^^^^^^^^^^^^^^^^^^^^^^
  File "C:\Users\matum\AppData\Local\Packages\PythonSoftwareFoundation.Python.3.11_qbz5n2kfra8p0\LocalCache\local-packages\Python311\site-packages\discord\app_commands\commands.py", line 876, in _do_call
    raise CommandInvokeError(self, e) from e
discord.app_commands.errors.CommandInvokeError: Command 'materials' raised an exception: ValueError: not enough values to unpack (expected 2, got 1)
2024-08-24 20:42:27,741 - WARNING - PyNaCl is not installed, voice will NOT be supported
2024-08-24 20:42:27,746 - INFO - 設定ファイルが再読み込みされました。
2024-08-24 20:42:27,751 - INFO - logging in using static token
2024-08-24 20:42:29,072 - INFO - Shard ID None has connected to Gateway (Session ID: 929c80633153df6bb3d3a3834d754f43).
2024-08-24 20:42:31,113 - INFO - ログインしました: レシピリサーチャーBot (814286584509104178)
2024-08-24 20:43:34,586 - WARNING - PyNaCl is not installed, voice will NOT be supported
2024-08-24 20:43:34,588 - INFO - 設定ファイルが再読み込みされました。
2024-08-24 20:43:34,591 - INFO - logging in using static token
2024-08-24 20:43:36,001 - INFO - Shard ID None has connected to Gateway (Session ID: 75ba35dfaee1e1b2ef0eed577051fe18).
2024-08-24 20:43:38,011 - INFO - ログインしました: レシピリサーチャーBot (814286584509104178)
2024-08-24 20:43:49,078 - ERROR - Ignoring exception in command 'materials'
Traceback (most recent call last):
  File "C:\Users\matum\AppData\Local\Packages\PythonSoftwareFoundation.Python.3.11_qbz5n2kfra8p0\LocalCache\local-packages\Python311\site-packages\discord\app_commands\commands.py", line 858, in _do_call
    return await self._callback(interaction, **params)  # type: ignore
           ^^^^^^^^^^^^^^^^^^^^^^^^^^^^^^^^^^^^^^^^^^^
  File "E:\Prg\Python\RecipeResearcher\RecipeResearcherBot_default_quantity.py", line 163, in materials
    key, value = line.strip().split(':')
    ^^^^^^^^^^
ValueError: not enough values to unpack (expected 2, got 1)

The above exception was the direct cause of the following exception:

Traceback (most recent call last):
  File "C:\Users\matum\AppData\Local\Packages\PythonSoftwareFoundation.Python.3.11_qbz5n2kfra8p0\LocalCache\local-packages\Python311\site-packages\discord\app_commands\tree.py", line 1310, in _call
    await command._invoke_with_namespace(interaction, namespace)
  File "C:\Users\matum\AppData\Local\Packages\PythonSoftwareFoundation.Python.3.11_qbz5n2kfra8p0\LocalCache\local-packages\Python311\site-packages\discord\app_commands\commands.py", line 883, in _invoke_with_namespace
    return await self._do_call(interaction, transformed_values)
           ^^^^^^^^^^^^^^^^^^^^^^^^^^^^^^^^^^^^^^^^^^^^^^^^^^^^
  File "C:\Users\matum\AppData\Local\Packages\PythonSoftwareFoundation.Python.3.11_qbz5n2kfra8p0\LocalCache\local-packages\Python311\site-packages\discord\app_commands\commands.py", line 876, in _do_call
    raise CommandInvokeError(self, e) from e
discord.app_commands.errors.CommandInvokeError: Command 'materials' raised an exception: ValueError: not enough values to unpack (expected 2, got 1)
2024-08-24 20:45:51,552 - WARNING - PyNaCl is not installed, voice will NOT be supported
2024-08-24 20:45:51,554 - INFO - 設定ファイルが再読み込みされました。
2024-08-24 20:45:51,557 - INFO - logging in using static token
2024-08-24 20:45:52,795 - INFO - Shard ID None has connected to Gateway (Session ID: 4a969d117e09104aa13b4cb65779096a).
2024-08-24 20:45:54,810 - INFO - ログインしました: レシピリサーチャーBot (814286584509104178)
2024-08-24 20:45:56,782 - ERROR - Ignoring exception in command 'materials'
Traceback (most recent call last):
  File "C:\Users\matum\AppData\Local\Packages\PythonSoftwareFoundation.Python.3.11_qbz5n2kfra8p0\LocalCache\local-packages\Python311\site-packages\discord\app_commands\commands.py", line 858, in _do_call
    return await self._callback(interaction, **params)  # type: ignore
           ^^^^^^^^^^^^^^^^^^^^^^^^^^^^^^^^^^^^^^^^^^^
  File "E:\Prg\Python\RecipeResearcher\RecipeResearcherBot_default_quantity.py", line 162, in materials
    key, value = line.strip().split(':')
    ^^^^^^^^^^
ValueError: not enough values to unpack (expected 2, got 1)

The above exception was the direct cause of the following exception:

Traceback (most recent call last):
  File "C:\Users\matum\AppData\Local\Packages\PythonSoftwareFoundation.Python.3.11_qbz5n2kfra8p0\LocalCache\local-packages\Python311\site-packages\discord\app_commands\tree.py", line 1310, in _call
    await command._invoke_with_namespace(interaction, namespace)
  File "C:\Users\matum\AppData\Local\Packages\PythonSoftwareFoundation.Python.3.11_qbz5n2kfra8p0\LocalCache\local-packages\Python311\site-packages\discord\app_commands\commands.py", line 883, in _invoke_with_namespace
    return await self._do_call(interaction, transformed_values)
           ^^^^^^^^^^^^^^^^^^^^^^^^^^^^^^^^^^^^^^^^^^^^^^^^^^^^
  File "C:\Users\matum\AppData\Local\Packages\PythonSoftwareFoundation.Python.3.11_qbz5n2kfra8p0\LocalCache\local-packages\Python311\site-packages\discord\app_commands\commands.py", line 876, in _do_call
    raise CommandInvokeError(self, e) from e
discord.app_commands.errors.CommandInvokeError: Command 'materials' raised an exception: ValueError: not enough values to unpack (expected 2, got 1)
2024-08-24 20:49:10,052 - WARNING - PyNaCl is not installed, voice will NOT be supported
2024-08-24 20:49:10,054 - INFO - 設定ファイルが再読み込みされました。
2024-08-24 20:49:10,057 - INFO - logging in using static token
2024-08-24 20:49:11,291 - INFO - Shard ID None has connected to Gateway (Session ID: 31b2f4024c2339e2c2e8746acc32e513).
2024-08-24 20:49:13,305 - INFO - ログインしました: レシピリサーチャーBot (814286584509104178)
2024-08-24 20:49:14,889 - ERROR - Ignoring exception in command 'materials'
Traceback (most recent call last):
  File "C:\Users\matum\AppData\Local\Packages\PythonSoftwareFoundation.Python.3.11_qbz5n2kfra8p0\LocalCache\local-packages\Python311\site-packages\discord\app_commands\commands.py", line 858, in _do_call
    return await self._callback(interaction, **params)  # type: ignore
           ^^^^^^^^^^^^^^^^^^^^^^^^^^^^^^^^^^^^^^^^^^^
  File "E:\Prg\Python\RecipeResearcher\RecipeResearcherBot_default_quantity.py", line 163, in materials
    key, value = line.strip().split(':')
    ^^^^^^^^^^
ValueError: not enough values to unpack (expected 2, got 1)

The above exception was the direct cause of the following exception:

Traceback (most recent call last):
  File "C:\Users\matum\AppData\Local\Packages\PythonSoftwareFoundation.Python.3.11_qbz5n2kfra8p0\LocalCache\local-packages\Python311\site-packages\discord\app_commands\tree.py", line 1310, in _call
    await command._invoke_with_namespace(interaction, namespace)
  File "C:\Users\matum\AppData\Local\Packages\PythonSoftwareFoundation.Python.3.11_qbz5n2kfra8p0\LocalCache\local-packages\Python311\site-packages\discord\app_commands\commands.py", line 883, in _invoke_with_namespace
    return await self._do_call(interaction, transformed_values)
           ^^^^^^^^^^^^^^^^^^^^^^^^^^^^^^^^^^^^^^^^^^^^^^^^^^^^
  File "C:\Users\matum\AppData\Local\Packages\PythonSoftwareFoundation.Python.3.11_qbz5n2kfra8p0\LocalCache\local-packages\Python311\site-packages\discord\app_commands\commands.py", line 876, in _do_call
    raise CommandInvokeError(self, e) from e
discord.app_commands.errors.CommandInvokeError: Command 'materials' raised an exception: ValueError: not enough values to unpack (expected 2, got 1)
2024-08-26 18:00:44,533 - WARNING - PyNaCl is not installed, voice will NOT be supported
2024-08-26 18:00:44,562 - INFO - 設定ファイルが再読み込みされました。
2024-08-26 18:00:44,567 - INFO - logging in using static token
2024-08-26 18:00:45,661 - INFO - Shard ID None has connected to Gateway (Session ID: 64646f995ba14dc89e5b9302e3391ce3).
2024-08-26 18:00:47,832 - INFO - ログインしました: レシピリサーチャーBot (814286584509104178)
2024-08-26 18:02:22,875 - ERROR - 材料コマンドの形式エラー: invalid literal for int() with base 10: ''
2024-08-27 14:31:05,290 - WARNING - PyNaCl is not installed, voice will NOT be supported
2024-08-27 14:31:05,321 - INFO - 設定ファイルが再読み込みされました。
2024-08-27 14:31:05,328 - INFO - logging in using static token
2024-08-27 14:31:07,856 - INFO - Shard ID None has connected to Gateway (Session ID: 801828db55cb2e83ab1e3086d58105c3).
2024-08-27 14:31:09,867 - INFO - ログインしました: レシピリサーチャーBot (814286584509104178)
2024-08-27 14:31:34,226 - ERROR - Ignoring exception in command 'materials'
Traceback (most recent call last):
  File "C:\Users\matum\AppData\Local\Packages\PythonSoftwareFoundation.Python.3.11_qbz5n2kfra8p0\LocalCache\local-packages\Python311\site-packages\discord\app_commands\commands.py", line 858, in _do_call
    return await self._callback(interaction, **params)  # type: ignore
           ^^^^^^^^^^^^^^^^^^^^^^^^^^^^^^^^^^^^^^^^^^^
  File "E:\Prg\Python\RecipeResearcher\Enhanced_RecipeResearcher.py", line 137, in materials
    total_materials, intermediate_materials = calculate_materials(materials_dict, df)
                                              ^^^^^^^^^^^^^^^^^^^^^^^^^^^^^^^^^^^^^^^
  File "E:\Prg\Python\RecipeResearcher\Enhanced_RecipeResearcher.py", line 66, in calculate_materials
    material = row[col].strip()
               ^^^^^^^^^^^^^^
AttributeError: 'float' object has no attribute 'strip'

The above exception was the direct cause of the following exception:

Traceback (most recent call last):
  File "C:\Users\matum\AppData\Local\Packages\PythonSoftwareFoundation.Python.3.11_qbz5n2kfra8p0\LocalCache\local-packages\Python311\site-packages\discord\app_commands\tree.py", line 1310, in _call
    await command._invoke_with_namespace(interaction, namespace)
  File "C:\Users\matum\AppData\Local\Packages\PythonSoftwareFoundation.Python.3.11_qbz5n2kfra8p0\LocalCache\local-packages\Python311\site-packages\discord\app_commands\commands.py", line 883, in _invoke_with_namespace
    return await self._do_call(interaction, transformed_values)
           ^^^^^^^^^^^^^^^^^^^^^^^^^^^^^^^^^^^^^^^^^^^^^^^^^^^^
  File "C:\Users\matum\AppData\Local\Packages\PythonSoftwareFoundation.Python.3.11_qbz5n2kfra8p0\LocalCache\local-packages\Python311\site-packages\discord\app_commands\commands.py", line 876, in _do_call
    raise CommandInvokeError(self, e) from e
discord.app_commands.errors.CommandInvokeError: Command 'materials' raised an exception: AttributeError: 'float' object has no attribute 'strip'
2024-08-27 14:31:57,728 - ERROR - Ignoring exception in command 'materials'
Traceback (most recent call last):
  File "C:\Users\matum\AppData\Local\Packages\PythonSoftwareFoundation.Python.3.11_qbz5n2kfra8p0\LocalCache\local-packages\Python311\site-packages\discord\app_commands\commands.py", line 858, in _do_call
    return await self._callback(interaction, **params)  # type: ignore
           ^^^^^^^^^^^^^^^^^^^^^^^^^^^^^^^^^^^^^^^^^^^
  File "E:\Prg\Python\RecipeResearcher\Enhanced_RecipeResearcher.py", line 137, in materials
    total_materials, intermediate_materials = calculate_materials(materials_dict, df)
                                              ^^^^^^^^^^^^^^^^^^^^^^^^^^^^^^^^^^^^^^^
  File "E:\Prg\Python\RecipeResearcher\Enhanced_RecipeResearcher.py", line 66, in calculate_materials
    material = row[col].strip()
               ^^^^^^^^^^^^^^
AttributeError: 'float' object has no attribute 'strip'

The above exception was the direct cause of the following exception:

Traceback (most recent call last):
  File "C:\Users\matum\AppData\Local\Packages\PythonSoftwareFoundation.Python.3.11_qbz5n2kfra8p0\LocalCache\local-packages\Python311\site-packages\discord\app_commands\tree.py", line 1310, in _call
    await command._invoke_with_namespace(interaction, namespace)
  File "C:\Users\matum\AppData\Local\Packages\PythonSoftwareFoundation.Python.3.11_qbz5n2kfra8p0\LocalCache\local-packages\Python311\site-packages\discord\app_commands\commands.py", line 883, in _invoke_with_namespace
    return await self._do_call(interaction, transformed_values)
           ^^^^^^^^^^^^^^^^^^^^^^^^^^^^^^^^^^^^^^^^^^^^^^^^^^^^
  File "C:\Users\matum\AppData\Local\Packages\PythonSoftwareFoundation.Python.3.11_qbz5n2kfra8p0\LocalCache\local-packages\Python311\site-packages\discord\app_commands\commands.py", line 876, in _do_call
    raise CommandInvokeError(self, e) from e
discord.app_commands.errors.CommandInvokeError: Command 'materials' raised an exception: AttributeError: 'float' object has no attribute 'strip'
2024-08-27 14:32:46,865 - WARNING - PyNaCl is not installed, voice will NOT be supported
2024-08-27 14:32:46,867 - INFO - 設定ファイルが再読み込みされました。
2024-08-27 14:32:46,870 - INFO - logging in using static token
2024-08-27 14:32:48,027 - INFO - Shard ID None has connected to Gateway (Session ID: 648b49c612b42a12b35a54b010879e06).
2024-08-27 14:32:50,038 - INFO - ログインしました: レシピリサーチャーBot (814286584509104178)
2024-08-27 14:32:52,086 - ERROR - Ignoring exception in command 'materials'
Traceback (most recent call last):
  File "C:\Users\matum\AppData\Local\Packages\PythonSoftwareFoundation.Python.3.11_qbz5n2kfra8p0\LocalCache\local-packages\Python311\site-packages\discord\app_commands\commands.py", line 858, in _do_call
    return await self._callback(interaction, **params)  # type: ignore
           ^^^^^^^^^^^^^^^^^^^^^^^^^^^^^^^^^^^^^^^^^^^
  File "E:\Prg\Python\RecipeResearcher\Enhanced_RecipeResearcher.py", line 146, in materials
    total_materials, intermediate_materials = calculate_materials(materials_dict, df)
                                              ^^^^^^^^^^^^^^^^^^^^^^^^^^^^^^^^^^^^^^^
  File "E:\Prg\Python\RecipeResearcher\Enhanced_RecipeResearcher.py", line 92, in calculate_materials
    for nested_material, nested_qty in nested_materials.items():
                                       ^^^^^^^^^^^^^^^^^^^^^^
AttributeError: 'tuple' object has no attribute 'items'

The above exception was the direct cause of the following exception:

Traceback (most recent call last):
  File "C:\Users\matum\AppData\Local\Packages\PythonSoftwareFoundation.Python.3.11_qbz5n2kfra8p0\LocalCache\local-packages\Python311\site-packages\discord\app_commands\tree.py", line 1310, in _call
    await command._invoke_with_namespace(interaction, namespace)
  File "C:\Users\matum\AppData\Local\Packages\PythonSoftwareFoundation.Python.3.11_qbz5n2kfra8p0\LocalCache\local-packages\Python311\site-packages\discord\app_commands\commands.py", line 883, in _invoke_with_namespace
    return await self._do_call(interaction, transformed_values)
           ^^^^^^^^^^^^^^^^^^^^^^^^^^^^^^^^^^^^^^^^^^^^^^^^^^^^
  File "C:\Users\matum\AppData\Local\Packages\PythonSoftwareFoundation.Python.3.11_qbz5n2kfra8p0\LocalCache\local-packages\Python311\site-packages\discord\app_commands\commands.py", line 876, in _do_call
    raise CommandInvokeError(self, e) from e
discord.app_commands.errors.CommandInvokeError: Command 'materials' raised an exception: AttributeError: 'tuple' object has no attribute 'items'
2024-08-27 14:35:35,792 - WARNING - PyNaCl is not installed, voice will NOT be supported
2024-08-27 14:35:35,794 - INFO - 設定ファイルが再読み込みされました。
2024-08-27 14:35:35,797 - INFO - logging in using static token
2024-08-27 14:35:36,832 - INFO - Shard ID None has connected to Gateway (Session ID: 3c6bc55e834ededd3d44a615e7e1f284).
2024-08-27 14:35:38,842 - INFO - ログインしました: レシピリサーチャーBot (814286584509104178)
2024-08-27 14:35:52,603 - ERROR - Ignoring exception in command 'materials'
Traceback (most recent call last):
  File "C:\Users\matum\AppData\Local\Packages\PythonSoftwareFoundation.Python.3.11_qbz5n2kfra8p0\LocalCache\local-packages\Python311\site-packages\discord\app_commands\commands.py", line 858, in _do_call
    return await self._callback(interaction, **params)  # type: ignore
           ^^^^^^^^^^^^^^^^^^^^^^^^^^^^^^^^^^^^^^^^^^^
  File "E:\Prg\Python\RecipeResearcher\Enhanced_RecipeResearcher.py", line 150, in materials
    total_materials, intermediate_materials = calculate_materials(materials_dict, df)
                                              ^^^^^^^^^^^^^^^^^^^^^^^^^^^^^^^^^^^^^^^
  File "E:\Prg\Python\RecipeResearcher\Enhanced_RecipeResearcher.py", line 90, in calculate_materials
    for intermediate_item, intermediate_qty in intermediate_materials.items():
RuntimeError: dictionary changed size during iteration

The above exception was the direct cause of the following exception:

Traceback (most recent call last):
  File "C:\Users\matum\AppData\Local\Packages\PythonSoftwareFoundation.Python.3.11_qbz5n2kfra8p0\LocalCache\local-packages\Python311\site-packages\discord\app_commands\tree.py", line 1310, in _call
    await command._invoke_with_namespace(interaction, namespace)
  File "C:\Users\matum\AppData\Local\Packages\PythonSoftwareFoundation.Python.3.11_qbz5n2kfra8p0\LocalCache\local-packages\Python311\site-packages\discord\app_commands\commands.py", line 883, in _invoke_with_namespace
    return await self._do_call(interaction, transformed_values)
           ^^^^^^^^^^^^^^^^^^^^^^^^^^^^^^^^^^^^^^^^^^^^^^^^^^^^
  File "C:\Users\matum\AppData\Local\Packages\PythonSoftwareFoundation.Python.3.11_qbz5n2kfra8p0\LocalCache\local-packages\Python311\site-packages\discord\app_commands\commands.py", line 876, in _do_call
    raise CommandInvokeError(self, e) from e
discord.app_commands.errors.CommandInvokeError: Command 'materials' raised an exception: RuntimeError: dictionary changed size during iteration
2024-08-27 14:37:02,564 - ERROR - Ignoring exception in command 'materials'
Traceback (most recent call last):
  File "C:\Users\matum\AppData\Local\Packages\PythonSoftwareFoundation.Python.3.11_qbz5n2kfra8p0\LocalCache\local-packages\Python311\site-packages\discord\app_commands\commands.py", line 858, in _do_call
    return await self._callback(interaction, **params)  # type: ignore
           ^^^^^^^^^^^^^^^^^^^^^^^^^^^^^^^^^^^^^^^^^^^
  File "E:\Prg\Python\RecipeResearcher\Enhanced_RecipeResearcher.py", line 150, in materials
    total_materials, intermediate_materials = calculate_materials(materials_dict, df)
                                              ^^^^^^^^^^^^^^^^^^^^^^^^^^^^^^^^^^^^^^^
  File "E:\Prg\Python\RecipeResearcher\Enhanced_RecipeResearcher.py", line 90, in calculate_materials
    for intermediate_item, intermediate_qty in intermediate_materials.items():
RuntimeError: dictionary changed size during iteration

The above exception was the direct cause of the following exception:

Traceback (most recent call last):
  File "C:\Users\matum\AppData\Local\Packages\PythonSoftwareFoundation.Python.3.11_qbz5n2kfra8p0\LocalCache\local-packages\Python311\site-packages\discord\app_commands\tree.py", line 1310, in _call
    await command._invoke_with_namespace(interaction, namespace)
  File "C:\Users\matum\AppData\Local\Packages\PythonSoftwareFoundation.Python.3.11_qbz5n2kfra8p0\LocalCache\local-packages\Python311\site-packages\discord\app_commands\commands.py", line 883, in _invoke_with_namespace
    return await self._do_call(interaction, transformed_values)
           ^^^^^^^^^^^^^^^^^^^^^^^^^^^^^^^^^^^^^^^^^^^^^^^^^^^^
  File "C:\Users\matum\AppData\Local\Packages\PythonSoftwareFoundation.Python.3.11_qbz5n2kfra8p0\LocalCache\local-packages\Python311\site-packages\discord\app_commands\commands.py", line 876, in _do_call
    raise CommandInvokeError(self, e) from e
discord.app_commands.errors.CommandInvokeError: Command 'materials' raised an exception: RuntimeError: dictionary changed size during iteration
2024-08-27 14:37:25,926 - ERROR - Ignoring exception in command 'materials'
Traceback (most recent call last):
  File "C:\Users\matum\AppData\Local\Packages\PythonSoftwareFoundation.Python.3.11_qbz5n2kfra8p0\LocalCache\local-packages\Python311\site-packages\discord\app_commands\commands.py", line 858, in _do_call
    return await self._callback(interaction, **params)  # type: ignore
           ^^^^^^^^^^^^^^^^^^^^^^^^^^^^^^^^^^^^^^^^^^^
  File "E:\Prg\Python\RecipeResearcher\Enhanced_RecipeResearcher.py", line 150, in materials
    total_materials, intermediate_materials = calculate_materials(materials_dict, df)
                                              ^^^^^^^^^^^^^^^^^^^^^^^^^^^^^^^^^^^^^^^
  File "E:\Prg\Python\RecipeResearcher\Enhanced_RecipeResearcher.py", line 90, in calculate_materials
    for intermediate_item, intermediate_qty in intermediate_materials.items():
RuntimeError: dictionary changed size during iteration

The above exception was the direct cause of the following exception:

Traceback (most recent call last):
  File "C:\Users\matum\AppData\Local\Packages\PythonSoftwareFoundation.Python.3.11_qbz5n2kfra8p0\LocalCache\local-packages\Python311\site-packages\discord\app_commands\tree.py", line 1310, in _call
    await command._invoke_with_namespace(interaction, namespace)
  File "C:\Users\matum\AppData\Local\Packages\PythonSoftwareFoundation.Python.3.11_qbz5n2kfra8p0\LocalCache\local-packages\Python311\site-packages\discord\app_commands\commands.py", line 883, in _invoke_with_namespace
    return await self._do_call(interaction, transformed_values)
           ^^^^^^^^^^^^^^^^^^^^^^^^^^^^^^^^^^^^^^^^^^^^^^^^^^^^
  File "C:\Users\matum\AppData\Local\Packages\PythonSoftwareFoundation.Python.3.11_qbz5n2kfra8p0\LocalCache\local-packages\Python311\site-packages\discord\app_commands\commands.py", line 876, in _do_call
    raise CommandInvokeError(self, e) from e
discord.app_commands.errors.CommandInvokeError: Command 'materials' raised an exception: RuntimeError: dictionary changed size during iteration
2024-08-27 14:59:02,435 - WARNING - PyNaCl is not installed, voice will NOT be supported
2024-08-27 14:59:02,436 - INFO - 設定ファイルが再読み込みされました。
2024-08-27 14:59:02,440 - INFO - logging in using static token
2024-08-27 14:59:03,643 - INFO - Shard ID None has connected to Gateway (Session ID: 0612c97f2410e2013aee8756a0b64712).
2024-08-27 14:59:05,650 - INFO - ログインしました: レシピリサーチャーBot (814286584509104178)
